<?xml version='1.0' encoding='UTF-8'?>
<robot name="hopper">

	<link name="base_link">
		<inertial>
			<origin rpy="0.00000 -0.00000 0.00000" xyz="0.00000 0.00000 0.00000"/>
			<mass value="0.00000"/>
			<inertia ixx="0.00000" ixy="0" ixz="0" iyy="0.00000" iyz="0" izz="0.00000"/>
		</inertial>
	</link>

	<link name="link0_2">
		<inertial>
			<origin rpy="0.00000 -0.00000 0.00000" xyz="0.00000 0.00000 0.00000"/>
			<mass value="0.00000"/>
			<inertia ixx="0.00000" ixy="0" ixz="0" iyy="0.00000" iyz="0" izz="0.00000"/>
		</inertial>
	</link>

	<link name="link0_3">
		<inertial>
			<origin rpy="0.00000 -0.00000 0.00000" xyz="0.00000 0.00000 0.00000"/>
			<mass value="0.00000"/>
			<inertia ixx="0.00000" ixy="0" ixz="0" iyy="0.00000" iyz="0" izz="0.00000"/>
		</inertial>
	</link>

	<link name="link0_4">
		<inertial>
			<origin rpy="0.00000 -0.00000 0.00000" xyz="0.00000 0.00000 0.00000"/>
			<mass value="0.00000"/>
			<inertia ixx="0.00000" ixy="0" ixz="0" iyy="0.00000" iyz="0" izz="0.00000"/>
		</inertial>
	</link>

	<link name="torso">
		<inertial>
			<origin rpy="0.00000 -0.00000 0.00000" xyz="0.00000 0.00000 0.2"/>
			<mass value="7.00"/>
			<inertia ixx="0.0977" ixy="0" ixz="0" iyy="0.0977" iyz="0" izz="0.00875"/>
		</inertial>
		<visual>
			<origin rpy="3.14159 -0.00000 3.14159" xyz="0.00000 0.00000 0.2"/>
			<geometry>
				<cylinder length="0.40000" radius="0.05000"/>
			</geometry>
        	<material name="red">
          		<color rgba="1 0.1 0.2 0.2"/>
        	</material>
		</visual>
		<collision>
			<origin rpy="3.14159 -0.00000 3.14159" xyz="0.00000 0.00000 0.2"/>
			<geometry>
				<cylinder length="0.40000" radius="0.05000"/>
			</geometry>
		</collision>
	</link>

	<link name="link0_6">
		<inertial>
			<origin rpy="0.00000 -0.00000 0.00000" xyz="0.00000 0.00000 0.00000"/>
			<mass value="0.00000"/>
			<inertia ixx="0.00000" ixy="0" ixz="0" iyy="0.00000" iyz="0" izz="0.00000"/>
		</inertial>
	</link>

	<link name="thigh">
		<inertial>
			<origin rpy="0.00000 -0.00000 0.00000" xyz="0.00000 0.00000 -0.225"/>
			<mass value="1.0"/>
			<inertia ixx="0.0175" ixy="0" ixz="0" iyy="0.0175" iyz="0" izz="0.00125"/>
		</inertial>
		<visual>
			<origin rpy="3.14159 -0.00000 3.14159" xyz="0.00000 0.00000 -0.225"/>
			<geometry>
				<cylinder length="0.45000" radius="0.05000"/>
			</geometry>
        	<material name="blue">
          		<color rgba="0 1.0 1.0 0.2"/>
        	</material>
		</visual>
		<collision>
			<origin rpy="3.14159 -0.00000 3.14159" xyz="0.00000 0.00000 -0.225"/>
			<geometry>
				<cylinder length="0.45000" radius="0.05000"/>
			</geometry>
		</collision>
	</link>

	<link name="link0_8">
		<inertial>
			<origin rpy="0.00000 -0.00000 0.00000" xyz="0.00000 0.00000 0.00000"/>
			<mass value="0.00000"/>
			<inertia ixx="0.00000" ixy="0" ixz="0" iyy="0.00000" iyz="0" izz="0.00000"/>
		</inertial>
	</link>

	<link name="leg">
		<inertial>
			<origin rpy="0.00000 -0.00000 0.00000" xyz="0.00000 0.00000 -0.25"/>
			<mass value="1.0"/>
			<inertia ixx="0.0215" ixy="0" ixz="0" iyy="0.0215" iyz="0" izz="0.00125"/>
		</inertial>

		<visual>
			<origin rpy="3.14159 -0.00000 3.14159" xyz="0.00000 0.00000 -0.25"/>
			<geometry>
				<cylinder length="0.50000" radius="0.05000"/>
			</geometry>
        	<material name="yellow">
          		<color rgba="0.5 1.0 0.0 0.2"/>
        	</material>
		</visual>

		<collision>
			<origin rpy="3.14159 -0.00000 3.14159" xyz="0.00000 0.00000 -0.25"/>
			<geometry>
				<cylinder length="0.50000" radius="0.0500"/>
			</geometry>
		</collision>
	</link>

	<link name="link0_10">
		<inertial>
			<origin rpy="0.00000 -0.00000 0.00000" xyz="0.00000 0.00000 0.00000"/>
			<mass value="0.00000"/>
			<inertia ixx="0.00000" ixy="0" ixz="0" iyy="0.00000" iyz="0" izz="0.00000"/>
		</inertial>
	</link>

	<link name="foot">
		<inertial>
			<origin rpy="0.00000 -0.00000 0.00000" xyz="0.06500 0.00000 0"/>
			<mass value="1.00"/>
			<inertia ixx="0.00125" ixy="0" ixz="0" iyy="0.0133" iyz="0" izz="0.0133"/>
		</inertial>

		<visual>
			<origin rpy="0.00000 1.57080 -0.00000" xyz="0.0650 0.00000 0"/>
			<geometry>
				<cylinder length="0.39000" radius="0.05000"/>
			</geometry>
        	<material name="cyan">
          		<color rgba="0 1.0 1.0 0.2"/>
        	</material>
		</visual>

		<collision>
			<origin rpy="0.00000 1.57080 -0.00000" xyz="0.06500 0.00000 0"/>
			<geometry>
				<cylinder length="0.39000" radius="0.05000"/>
			</geometry>
		</collision>
	</link>

	<link name="toe">
		<inertial>
			<origin rpy="0.00000 -0.00000 0.00000" xyz="0.00000 0.00000 0.00000"/>
			<mass value="0.00000"/>
			<inertia ixx="0.00000" ixy="0" ixz="0" iyy="0.00000" iyz="0" izz="0.00000"/>
		</inertial>
		<visual>
			<origin rpy="0.00000 0 -0.00000" xyz="0 0.00000 0"/>
			<geometry>
				<sphere radius="0.01"/>
			</geometry>
        	<material name="Cyan">
          		<color rgba="1 0 0 0.2"/>
        	</material>
		</visual>
		<collision>
			<origin rpy="0.00000 0 -0.00000" xyz="0 0.00000 0"/>
			<geometry>
				<sphere radius="0.01"/>
			</geometry>
		</collision>
	</link>

	<link name="heel">
		<inertial>
			<origin rpy="0.00000 -0.00000 0.00000" xyz="0.00000 0.00000 0.00000"/>
			<mass value="0.00000"/>
			<inertia ixx="0.00000" ixy="0" ixz="0" iyy="0.00000" iyz="0" izz="0.00000"/>
		</inertial>
		<visual>
			<origin rpy="0.00000 0 -0.00000" xyz="0 0.00000 0"/>
			<geometry>
				<sphere radius="0.01"/>
			</geometry>
        	<material name="Cyan">
          		<color rgba="1 0 0 0.2"/>
        	</material>
		</visual>
		<collision>
			<origin rpy="0.00000 0 -0.00000" xyz="0 0.00000 0"/>
			<geometry>
				<sphere radius="0.01"/>
			</geometry>
		</collision>
	</link>

	<joint name="ignore1" type="prismatic">
		<parent link="base_link"/>
		<child link="link0_2"/>
		<dynamics damping="1.0" friction="0.0001"/>
		<origin rpy="0.00000 -0.00000 0.00000" xyz="0.00000 0.00000 0.00000"/>
		<axis xyz="1.00000 0.00000 0.00000"/>
		<limit lower="-100" upper="100" effort="100" velocity="100"/>
	</joint>

	<joint name="ignore2" type="prismatic">
		<parent link="link0_2"/>
		<child link="link0_3"/>
		<dynamics damping="1.0" friction="0.0001"/>
		<origin rpy="0.00000 -0.00000 0.00000" xyz="0.00000 0.00000 0.00000"/>
		<axis xyz="0.00000 0.00000 1.00000"/>
		<limit lower="-1.05" upper="2" effort="100" velocity="100"/>
	</joint>

	<joint name="ignore3" type="continuous">
		<parent link="link0_3"/>
		<child link="link0_4"/>
		<dynamics damping="1.0" friction="0.0001"/>
		<origin rpy="0.00000 -0.00000 0.00000" xyz="0.00000 0.00000 0.00000"/>
		<axis xyz="0.00000 1.00000 0.00000"/>
		<limit lower="-3.14" upper="3.14" effort="100" velocity="100"/>
	</joint>

	<joint name="jointfix_3_4" type="fixed">
		<parent link="link0_4"/>
		<child link="torso"/>
	</joint>

	<joint name="thigh_joint" type="revolute">
		<parent link="torso"/>
		<child link="link0_6"/>
		<dynamics damping="1.0" friction="0.0001"/>
		<origin rpy="0.00000 -0.00000 0.00000" xyz="0.00000 0.00000 0"/>
		<axis xyz="0.00000 -1.00000 0.00000"/>
		<limit lower="-1.4" upper="0.5" effort="50" velocity="30"/>
		<!-- <limit lower="-0.5" upper="1.4" effort="50" velocity="30"/> -->
	</joint>

	<joint name="jointfix_2_6" type="fixed">
		<parent link="link0_6"/>
		<child link="thigh"/>
		<dynamics damping="1.0" friction="0.0001"/>
		<origin rpy="0.00000 -0.00000 0.00000" xyz="0.00000 0.00000 0"/>
		<axis xyz="0.00000 0.00000 0.00000"/>
	</joint>

	<joint name="leg_joint" type="revolute">
		<parent link="thigh"/>
		<child link="link0_8"/>
		<dynamics damping="1.0" friction="0.0001"/>
		<origin rpy="0.00000 -0.00000 0.00000" xyz="0.00000 0.00000 -0.45"/>
		<axis xyz="0.00000 -1.00000 0.00000"/>
		<limit lower="-0.5" upper="2.2" effort="50" velocity="30"/>
		<!-- <limit lower="-2.2" upper="0.5" effort="50" velocity="30"/> -->
	</joint>

	<joint name="jointfix_1_8" type="fixed">
		<parent link="link0_8"/>
		<child link="leg"/>
		<dynamics damping="1.0" friction="0.0001"/>
		<origin rpy="0.00000 -0.00000 0.00000" xyz="0.00000 0.00000 0"/>
		<axis xyz="0.00000 0.00000 0.00000"/>
	</joint>

	<joint name="foot_joint" type="revolute">
		<parent link="leg"/>
		<child link="link0_10"/>
		<dynamics damping="1.0" friction="0.0001"/>
		<origin rpy="0.00000 -0.00000 0.00000" xyz="0.00000 0.00000 -0.50"/>
		<axis xyz="0.00000 -1.00000 0.00000"/>
		<limit lower="-1.1" upper="1.1" effort="50" velocity="30"/>
	</joint>

	<joint name="jointfix_0_10" type="fixed">
		<parent link="link0_10"/>
		<child link="foot"/>
		<dynamics damping="1.0" friction="0.0001"/>
		<origin rpy="0.00000 -0.00000 0.00000" xyz="0.00000 0.00000 0"/>
		<axis xyz="0.00000 0.00000 0.00000"/>
	</joint>

	<joint name="foot_toe" type="fixed">
		<parent link="foot"/>
		<child link="toe"/>
		<dynamics damping="1.0" friction="0.0001"/>
		<origin rpy="0.00000 -0.00000 0.00000" xyz="0.26 0.00000 -0.045"/>
		<axis xyz="0.00000 0.00000 0.00000"/>
	</joint>

	<joint name="foot_heel" type="fixed">
		<parent link="foot"/>
		<child link="heel"/>
		<dynamics damping="1.0" friction="0.0001"/>
		<origin rpy="0.00000 -0.00000 0.00000" xyz="-0.13 0.00000 -0.045"/>
		<axis xyz="0.00000 0.00000 0.00000"/>
	</joint>
</robot>